<?xml version="1.0"?>
<robot name="human_mallet">

  <material name="red">
    <color rgba="1 0 0 1"/>
  </material>  

  <material name="blue">
    <color rgba="0.2745 0.5098 0.7059 1"/>
  </material>

  <material name="black">
    <color rgba="0 0 0 1"/>
  </material>  

  <link name="base_link">
    <visual>
      <geometry>
        <cylinder length="0.1" radius="0.45"/>
      </geometry>
      <material name="black"/>
    </visual>
    <collision>
      <surface>
        <bounce restitution_coefficient="1.0" threshold="0.01"/>
      </surface>
      <geometry>
        <cylinder length="0.1" radius="0.40"/>
      </geometry>
    </collision>
    <inertial>  
        <mass value="2.5"/>
        <inertia ixx="0.1" ixy="0" ixz="0" iyy="0.1" iyz="0" izz="0.2"/>
    </inertial>
    <contact>
      <lateral_friction value="0"/>
      <restitution value="0.0" /> 
    </contact>
  </link>

  <link name="manipulator">
    <visual>
      <geometry>
        <cylinder length="0.4" radius="0.25"/>
      </geometry>
      <material name="blue"/>
    </visual>
    <collision>
      <geometry>
        <cylinder length="0.4" radius="0.35"/>
      </geometry>
    </collision>
    <inertial> 
        <mass value="10"/>
        <inertia ixx="0.2" ixy="0" ixz="0" iyy="0.2" iyz="0.0" izz="0.2"/>
    </inertial>
  </link>

  <link name="world">
    <inertial>
      <mass value="0"/>
      <origin rpy="0 0 0" xyz="0 0 0"/>
      <inertia ixx="0" ixy="0" ixz="0" iyy="0" iyz="0" izz="0"/>
    </inertial>
  </link>

  <link name="y_prismatic">
    <inertial>
      <mass value="0.01"/>
      <inertia ixx="0.2125" ixy="-0.005" ixz="0.0225" iyy="0.205" iyz="0.045" izz="0.0125"/>
      <origin rpy="0 0 0" xyz="0 0 0"/>
    </inertial>
  </link>

  <link name="x_prismatic">
    <inertial>
      <mass value="0.0"/>
      <inertia ixx="0" ixy="0.0" ixz="0.0" iyy="0.0" iyz="0.0" izz="0.0"/>
      <origin rpy="0 0 0" xyz="0 0 0"/>
    </inertial>
  </link>

  <joint name="x_to_y" type="prismatic">
    <parent link="y_prismatic"/>
    <child link="x_prismatic"/>
    <axis xyz="0 1 0"/>
    <limit effort="0.0" lower="1" upper="-1" velocity="1000.0"/>
    <origin rpy="0 0 0" xyz="0 0 0"/>
  </joint>

  <joint name="y_to_world" type="prismatic">
    <parent link="world"/>
    <child link="y_prismatic"/>
    <axis xyz="1 0 0"/>
    <limit effort="0.0" lower="1" upper="-1" velocity="1000.0"/>
    <origin rpy="0 0 0" xyz="0 0 0"/>
  </joint>
  
  <joint name="base_to_x" type="continuous">
    <parent link="x_prismatic"/>
    <child link="base_link"/>
    <axis xyz="0 0 1"/>
    <origin rpy="0 0 0" xyz="0 0 0"/>
  </joint>

  <joint name="base_to_manipulator" type="fixed">
    <parent link="base_link"/>
    <child link="manipulator"/>
    <origin xyz="0 0 0.2"/>
  </joint>


</robot>

